Restoring states from the checkpoint path at checkpoints/example.ckpt
Lightning automatically upgraded your loaded checkpoint from v1.9.3 to v2.1.3. To apply the upgrade to your files permanently, run `python -m pytorch_lightning.utilities.upgrade_checkpoint checkpoints/example.ckpt`
LOCAL_RANK: 0 - CUDA_VISIBLE_DEVICES: [4,5,6,7]
Loaded model weights from the checkpoint at checkpoints/example.ckpt
Traceback (most recent call last):
  File "lctgen/main.py", line 89, in <module>
    main()
  File "lctgen/main.py", line 48, in main
    run_exp(**vars(args))
  File "lctgen/main.py", line 86, in run_exp
    execute_exp(config, run_type)
  File "lctgen/main.py", line 66, in execute_exp
    trainer.eval()
  File "/GPFS/rhome/xiajunkai/lctgen/lctgen/trainer.py", line 194, in eval
    self.trainer.test(model=self.lightning_model, dataloaders=self.data_loaders['test'], ckpt_path=ckpt_path)
  File "/GPFS/rhome/xiajunkai/miniconda3/envs/lctgen/lib/python3.8/site-packages/pytorch_lightning/trainer/trainer.py", line 754, in test
    return call._call_and_handle_interrupt(
  File "/GPFS/rhome/xiajunkai/miniconda3/envs/lctgen/lib/python3.8/site-packages/pytorch_lightning/trainer/call.py", line 43, in _call_and_handle_interrupt
    return trainer.strategy.launcher.launch(trainer_fn, *args, trainer=trainer, **kwargs)
  File "/GPFS/rhome/xiajunkai/miniconda3/envs/lctgen/lib/python3.8/site-packages/pytorch_lightning/strategies/launchers/subprocess_script.py", line 102, in launch
    return function(*args, **kwargs)
  File "/GPFS/rhome/xiajunkai/miniconda3/envs/lctgen/lib/python3.8/site-packages/pytorch_lightning/trainer/trainer.py", line 794, in _test_impl
    results = self._run(model, ckpt_path=ckpt_path)
  File "/GPFS/rhome/xiajunkai/miniconda3/envs/lctgen/lib/python3.8/site-packages/pytorch_lightning/trainer/trainer.py", line 989, in _run
    results = self._run_stage()
  File "/GPFS/rhome/xiajunkai/miniconda3/envs/lctgen/lib/python3.8/site-packages/pytorch_lightning/trainer/trainer.py", line 1028, in _run_stage
    return self._evaluation_loop.run()
  File "/GPFS/rhome/xiajunkai/miniconda3/envs/lctgen/lib/python3.8/site-packages/pytorch_lightning/loops/utilities.py", line 182, in _decorator
    return loop_run(self, *args, **kwargs)
  File "/GPFS/rhome/xiajunkai/miniconda3/envs/lctgen/lib/python3.8/site-packages/pytorch_lightning/loops/evaluation_loop.py", line 127, in run
    batch, batch_idx, dataloader_idx = next(data_fetcher)
  File "/GPFS/rhome/xiajunkai/miniconda3/envs/lctgen/lib/python3.8/site-packages/pytorch_lightning/loops/fetchers.py", line 127, in __next__
    batch = super().__next__()
  File "/GPFS/rhome/xiajunkai/miniconda3/envs/lctgen/lib/python3.8/site-packages/pytorch_lightning/loops/fetchers.py", line 56, in __next__
    batch = next(self.iterator)
  File "/GPFS/rhome/xiajunkai/miniconda3/envs/lctgen/lib/python3.8/site-packages/pytorch_lightning/utilities/combined_loader.py", line 326, in __next__
    out = next(self._iterator)
  File "/GPFS/rhome/xiajunkai/miniconda3/envs/lctgen/lib/python3.8/site-packages/pytorch_lightning/utilities/combined_loader.py", line 132, in __next__
    out = next(self.iterators[0])
  File "/GPFS/rhome/xiajunkai/miniconda3/envs/lctgen/lib/python3.8/site-packages/torch/utils/data/dataloader.py", line 681, in __next__
    data = self._next_data()
  File "/GPFS/rhome/xiajunkai/miniconda3/envs/lctgen/lib/python3.8/site-packages/torch/utils/data/dataloader.py", line 1376, in _next_data
    return self._process_data(data)
  File "/GPFS/rhome/xiajunkai/miniconda3/envs/lctgen/lib/python3.8/site-packages/torch/utils/data/dataloader.py", line 1402, in _process_data
    data.reraise()
  File "/GPFS/rhome/xiajunkai/miniconda3/envs/lctgen/lib/python3.8/site-packages/torch/_utils.py", line 461, in reraise
    raise exception
FileNotFoundError: Caught FileNotFoundError in DataLoader worker process 0.
Original Traceback (most recent call last):
  File "/GPFS/rhome/xiajunkai/miniconda3/envs/lctgen/lib/python3.8/site-packages/torch/utils/data/_utils/worker.py", line 302, in _worker_loop
    data = fetcher.fetch(index)
  File "/GPFS/rhome/xiajunkai/miniconda3/envs/lctgen/lib/python3.8/site-packages/torch/utils/data/_utils/fetch.py", line 49, in fetch
    data = [self.dataset[idx] for idx in possibly_batched_index]
  File "/GPFS/rhome/xiajunkai/miniconda3/envs/lctgen/lib/python3.8/site-packages/torch/utils/data/_utils/fetch.py", line 49, in <listcomp>
    data = [self.dataset[idx] for idx in possibly_batched_index]
  File "/GPFS/rhome/xiajunkai/lctgen/lctgen/datasets/waymo_open_motion.py", line 54, in __getitem__
    data = self._get_item_helper(index)
  File "/GPFS/rhome/xiajunkai/lctgen/lctgen/datasets/waymo_open_motion.py", line 105, in _get_item_helper
    with open(data_file_path, 'rb') as f:
FileNotFoundError: [Errno 2] No such file or directory: 'data/demo/waymo/5_2823.pkl'
Traceback (most recent call last):
  File "lctgen/main.py", line 89, in <module>
    main()
  File "lctgen/main.py", line 48, in main
    run_exp(**vars(args))
  File "lctgen/main.py", line 86, in run_exp
    execute_exp(config, run_type)
  File "lctgen/main.py", line 66, in execute_exp
    trainer.eval()
  File "/GPFS/rhome/xiajunkai/lctgen/lctgen/trainer.py", line 194, in eval
    self.trainer.test(model=self.lightning_model, dataloaders=self.data_loaders['test'], ckpt_path=ckpt_path)
  File "/GPFS/rhome/xiajunkai/miniconda3/envs/lctgen/lib/python3.8/site-packages/pytorch_lightning/trainer/trainer.py", line 754, in test
    return call._call_and_handle_interrupt(
  File "/GPFS/rhome/xiajunkai/miniconda3/envs/lctgen/lib/python3.8/site-packages/pytorch_lightning/trainer/call.py", line 43, in _call_and_handle_interrupt
    return trainer.strategy.launcher.launch(trainer_fn, *args, trainer=trainer, **kwargs)
  File "/GPFS/rhome/xiajunkai/miniconda3/envs/lctgen/lib/python3.8/site-packages/pytorch_lightning/strategies/launchers/subprocess_script.py", line 102, in launch
    return function(*args, **kwargs)
  File "/GPFS/rhome/xiajunkai/miniconda3/envs/lctgen/lib/python3.8/site-packages/pytorch_lightning/trainer/trainer.py", line 794, in _test_impl
    results = self._run(model, ckpt_path=ckpt_path)
  File "/GPFS/rhome/xiajunkai/miniconda3/envs/lctgen/lib/python3.8/site-packages/pytorch_lightning/trainer/trainer.py", line 989, in _run
    results = self._run_stage()
  File "/GPFS/rhome/xiajunkai/miniconda3/envs/lctgen/lib/python3.8/site-packages/pytorch_lightning/trainer/trainer.py", line 1028, in _run_stage
    return self._evaluation_loop.run()
  File "/GPFS/rhome/xiajunkai/miniconda3/envs/lctgen/lib/python3.8/site-packages/pytorch_lightning/loops/utilities.py", line 182, in _decorator
    return loop_run(self, *args, **kwargs)
  File "/GPFS/rhome/xiajunkai/miniconda3/envs/lctgen/lib/python3.8/site-packages/pytorch_lightning/loops/evaluation_loop.py", line 127, in run
    batch, batch_idx, dataloader_idx = next(data_fetcher)
  File "/GPFS/rhome/xiajunkai/miniconda3/envs/lctgen/lib/python3.8/site-packages/pytorch_lightning/loops/fetchers.py", line 127, in __next__
    batch = super().__next__()
  File "/GPFS/rhome/xiajunkai/miniconda3/envs/lctgen/lib/python3.8/site-packages/pytorch_lightning/loops/fetchers.py", line 56, in __next__
    batch = next(self.iterator)
  File "/GPFS/rhome/xiajunkai/miniconda3/envs/lctgen/lib/python3.8/site-packages/pytorch_lightning/utilities/combined_loader.py", line 326, in __next__
    out = next(self._iterator)
  File "/GPFS/rhome/xiajunkai/miniconda3/envs/lctgen/lib/python3.8/site-packages/pytorch_lightning/utilities/combined_loader.py", line 132, in __next__
    out = next(self.iterators[0])
  File "/GPFS/rhome/xiajunkai/miniconda3/envs/lctgen/lib/python3.8/site-packages/torch/utils/data/dataloader.py", line 681, in __next__
    data = self._next_data()
  File "/GPFS/rhome/xiajunkai/miniconda3/envs/lctgen/lib/python3.8/site-packages/torch/utils/data/dataloader.py", line 1376, in _next_data
    return self._process_data(data)
  File "/GPFS/rhome/xiajunkai/miniconda3/envs/lctgen/lib/python3.8/site-packages/torch/utils/data/dataloader.py", line 1402, in _process_data
    data.reraise()
  File "/GPFS/rhome/xiajunkai/miniconda3/envs/lctgen/lib/python3.8/site-packages/torch/_utils.py", line 461, in reraise
    raise exception
FileNotFoundError: Caught FileNotFoundError in DataLoader worker process 0.
Original Traceback (most recent call last):
  File "/GPFS/rhome/xiajunkai/miniconda3/envs/lctgen/lib/python3.8/site-packages/torch/utils/data/_utils/worker.py", line 302, in _worker_loop
    data = fetcher.fetch(index)
  File "/GPFS/rhome/xiajunkai/miniconda3/envs/lctgen/lib/python3.8/site-packages/torch/utils/data/_utils/fetch.py", line 49, in fetch
    data = [self.dataset[idx] for idx in possibly_batched_index]
  File "/GPFS/rhome/xiajunkai/miniconda3/envs/lctgen/lib/python3.8/site-packages/torch/utils/data/_utils/fetch.py", line 49, in <listcomp>
    data = [self.dataset[idx] for idx in possibly_batched_index]
  File "/GPFS/rhome/xiajunkai/lctgen/lctgen/datasets/waymo_open_motion.py", line 54, in __getitem__
    data = self._get_item_helper(index)
  File "/GPFS/rhome/xiajunkai/lctgen/lctgen/datasets/waymo_open_motion.py", line 105, in _get_item_helper
    with open(data_file_path, 'rb') as f:
FileNotFoundError: [Errno 2] No such file or directory: 'data/demo/waymo/5_2823.pkl'
Testing: |                                                                                                                      | 0/? [00:00<?, ?it/s]